Workbook
Name A1462A1: #REF!
Name Slicer_brand_name: #N/A
Name Slicer_brand_name1: #N/A
Name Slicer_product_category: #N/A

Sheet Sheet1
A1: product_name | B1: brand_name | C1: rating | D1: rating_count | E1: marked_price | F1: discounted_price | G1: sizes | H1: product_link
A2: Slim Fit Casual Shirt | B2: Greenfibre | C2: 0 | D2: 0 | E2: 1699 | F2: 1699 | G2: 38,39,40,42,44 | H2: shirts/greenfibre/greenfibre-men-yellow-slim-fit-checked-casual-shirt/18427366/buy
A3: Men Printed T-shirt | B3: FREESOUL | C3: 0 | D3: 0 | E3: 799 | F3: 799 | G3: S,M,L,XL,XXL | H3: tshirts/freesoul/freesoul-men-white-printed-cotton-t-shirt/18069688/buy
A4: Leather Two Fold Wallet | B4: Da Milano | C4: 0 | D4: 0 | E4: 4499 | F4: 4499 | G4: Onesize | H4: wallets/da-milano/da-milano-women-blue-textured-leather-two-fold-wallet/18013592/buy
A5: Pure Georgette Bandhani Saree | B5: Mitera | C5: 3.6 | D5: 5 | E5: 6727 | F5: 1681 | G5: Onesize | H5: sarees/mitera/mitera-women-sea-green--white-embroidered-pure-georgette-bandhani-saree/17141476/buy
A6: Men Geometric Printed Kurta | B6: Indo Era | C6: 0 | D6: 0 | E6: 2599 | F6: 1429 | G6: S,M,L,XL,XXL | H6: kurtas/indo-era/indo-era-men-lavender-geometric-printed-kurta/17502668/buy
A7: Men Accessory Gift Set | B7: WildHorn | C7: 4.5 | D7: 80 | E7: 2999 | F7: 1049 | G7: Onesize | H7: accessory-gift-set/wildhorn/wildhorn-men-accessory-gift-set/1410357/buy
A8: Self-Design Thermal Set | B8: Kanvin | C8: 4.6 | D8: 42 | E8: 1598 | F8: 1278 | G8: S,M,L,XL,XXL | H8: thermal-set/kanvin/kanvin-off-white-self-design-thermal-set-new2150ow2180/2223155/buy
A9: Men Slim Fit T-shirt | B9: Jack & Jones | C9: 3.7 | D9: 7 | E9: 1299 | F9: 649 | G9: S,M,L,XL,XXL | H9: tshirts/jack--jones/jack--jones-men-blue-slim-fit-t-shirt/15430520/buy
A10: Block Print Pure Georgette Saree | B10: MS RETAIL | C10: 0 | D10: 0 | E10: 1015 | F10: 497 | G10: Onesize | H10: sarees/ms-retail/ms-retail-green--white-pure-georgette-block-print-saree/18467984/buy
A11: Outdoor Rapid-Dry Jacket | B11: HRX by Hrithik Roshan | C11: 4.4 | D11: 186 | E11: 2799 | F11: 1679 | G11: XS,S,M,L,XL | H11: jackets/hrx-by-hrithik-roshan/hrx-by-hrithik-roshan-women-navy-colourblocked-rapid-dry-antimicrobial-outdoor-jacket/11953112/buy
A12: Floral Maxi Dress | B12: Nayo | C12: 4 | D12: 7 | E12: 1999 | F12: 799 | G12: S,M,L,XL,XXL | H12: dresses/nayo/nayo-pink--white-floral-ethnic-maxi-dress/17634118/buy
A13: Women Ribbed Fitted Top | B13: DressBerry | C13: 4.2 | D13: 252 | E13: 999 | F13: 399 | G13: XS,S,M,L,XL | H13: tops/dressberry/dressberry-women-mustard-yellow-ribbed-fitted-top/11003624/buy
... A52: Textured Block Sandals with Laser Cuts | B52: ERIDANI | C52: 0 | D52: 0 | E52: 1799 | F52: 1799 | G52: EURO35,EURO36,EURO37,EURO38,EURO39,EURO40,EURO41 | H52: heels/eridani/eridani-black-textured-block-sandals-with-laser-cuts/18711914/buy
A53: Slim Fit Formal Shirt | B53: Greenfibre | C53: 0 | D53: 0 | E53: 1549 | F53: 1549 | G53: 46 | H53: shirts/greenfibre/greenfibre-men-blue-slim-fit-checked-formal-shirt/18427508/buy
A54: Coconut Conditioner 350 ml | B54: MYSTIC VALLEY | C54: 0 | D54: 0 | E54: 1425 | F54: 1425 | G54: 100-350 ML | H54: shampoo-and-conditioner/mystic-valley/mystic-valley-coconut-chimera--mineral-bays-anti-breakage-soft-hair-conditioner-350-ml/18356878/buy
A55: Solid Workout Bra | B55: Alcis | C55: 0 | D55: 0 | E55: 1899 | F55: 1899 | G55: XS,S,M,L,XL | H55: bra/alcis/alcis-lime-green--solid-workout-bra/18255544/buy
A56: Floral Maxi Dress | B56: BoStreet | C56: 0 | D56: 0 | E56: 1999 | F56: 1719 | G56: S,M,L,XL,XXL,3XL | H56: dresses/bostreet/bostreet-blue-floral-maxi-dress/18246992/buy
A57: Women Kurta Set | B57: Seerat | C57: 2.5 | D57: 4 | E57: 7900 | F57: 7110 | G57: XS,S,M,L,XL,XXL | H57: kurta-sets/seerat/seerat-women-green--yellow-ethnic-motifs-pure-silk-kurta-with-trousers--dupatta/16492866/buy
A58: Structured Handheld Bag | B58: Lavie | C58: 0 | D58: 0 | E58: 4490 | F58: 2469 | G58: M | H58: handbags/lavie/lavie-beige-textured-structured-handheld-bag/15017978/buy
A59: Dobby Weave Ruffles Detail Top | B59: Mast & Harbour | C59: 0 | D59: 0 | E59: 1499 | F59: 674 | G59: XS,S,M,L,XL | H59: tops/mast--harbour/mast--harbour-rust-red-dobby-weave-ruffles-detail-top/15287534/buy
A60: Dobby Woven Design Dupatta | B60: Juniper | C60: 4.2 | D60: 85 | E60: 1049 | F60: 314 | G60: Onesize | H60: dupatta/juniper/juniper-off-white--black-dobby-woven-design-dupatta/11478462/buy
A61: Men Slim Fit Running Sports Shorts | B61: FITINC | C61: 0 | D61: 0 | E61: 999 | F61: 499 | G61: 30,32,34,37,40 | H61: shorts/fitinc/fitinc-men-grey-slim-fit-running-sports-shorts/18355614/buy
A62: Men RCB Baseball Cap | B62: Puma | C62: 4.1 | D62: 46 | E62: 899 | F62: 494 | G62: Onesize | H62: caps/puma/puma-men-red--navy-blue-printed-royal-challengers-baseball-cap/13984064/buy
A63: Boys Floral Printed V-Neck T-shirt | B63: max | C63: 4.5 | D63: 27 | E63: 199 | F63: 199 | G63: 6-12M,12-18M,18-24M | H63: tshirts/max/max-boys-white--black-printed-v-neck-tropical-t-shirt/17425494/buy
A64: Women Analogue Watch | B64: LOIS CARON | C64: 4.2 | D64: 16 | E64: 3999 | F64: 719 | G64: Onesize | H64: watches/lois-caron/lois-caron-women-gold-toned-analogue-watch-mlc-8620/14448140/buy
A65: Women Printed Crepe Kurta | B65: KALINI | C65: 0 | D65: 0 | E65: 999 | F65: 399 | G65: S,M,L,XL,XXL,3XL,4XL | H65: kurtas/kalini/kalini-women-blue--black-printed-crepe-kurta/17075664/buy
... A260: Men Printed Cotton T-shirt | B260: Jolie robe | C260: 0 | D260: 0 | E260: 1299 | F260: 519 | G260: S,M,L,XL,XXL | H260: tshirts/jolie-robe/jolie-robe-men-charcoal-grey--green-graphic-printed-cotton-t-shirt/18103534/buy
A261: Formal Shirt | B261: JADE BLUE | C261: 0 | D261: 0 | E261: 2749 | F261: 2749 | G261: 46 | H261: shirts/jade-blue/jade-blue-men-green-formal-shirt/18428308/buy
A262: Women Analogue Watch | B262: Fossil | C262: 4.4 | D262: 81 | E262: 10995 | F262: 10995 | G262: Onesize | H262: watches/fossil/fossil-women-black-analogue-watch-es4519sor/9037953/buy
A263: Solid Shoulder Bag | B263: Lino Perros | C263: 4.4 | D263: 296 | E263: 3495 | F263: 1887 | G263: Onesize | H263: handbags/lino-perros/lino-perros-pink-solid-shoulder-bag/2155170/buy
A264: Men Polo Collar T-shirt | B264: Red Tape | C264: 0 | D264: 0 | E264: 3099 | F264: 1049 | G264: S,M,L,XL,XXL | H264: tshirts/red-tape/red-tape-men-blue-polo-collar-pure-cotton-t-shirt/17672120/buy
A265: Men Polycotton Lounge Pants | B265: max | C265: 4.8 | D265: 10 | E265: 699 | F265: 699 | G265: S,M,L,XL,XXL | H265: lounge-pants/max/max-men-navy-blue-solid-mid-rise-polycotton-lounge-pants/17593908/buy
A266: Men Typography Printed T-shirt | B266: Moda Rapido | C266: 4.2 | D266: 13 | E266: 899 | F266: 431 | G266: S,M,L,XL | H266: tshirts/moda-rapido/moda-rapido-men-pink-typography-printed-pure-cotton-t-shirt/17108186/buy
A267: Ethnic Motif A-Line Kurta | B267: mokshi | C267: 3.7 | D267: 49 | E267: 2499 | F267: 699 | G267: S,M,L,XL,XXL | H267: kurtas/mokshi/mokshi-women-navy-blue--beige-ethnic-motif-foil-print-a-line-kurta/12764720/buy
A268: Nail Lacquer - Bumble Bee | B268: Colorbar | C268: 4.5 | D268: 170 | E268: 199 | F268: 199 | G268: Onesize | H268: nail-polish/colorbar/colorbar-nail-lacquer---bumble-bee-12ml/8862403/buy
A269: Men Skinny Fit Jeans | B269: Flying Machine | C269: 0 | D269: 0 | E269: 2299 | F269: 1609 | G269: 30,32,34,36,38 | H269: jeans/flying-machine/flying-machine-men-blue-jackson-skinny-fit-mid-rise-light-fade-stretchable-jeans/17097906/buy
A270: Boys Printed Cotton Kurta | B270: House of Pataudi | C270: 0 | D270: 0 | E270: 899 | F270: 899 | G270: 8-9Y,10-11Y,11-12Y,13-14Y | H270: kurtas/house-of-pataudi/house-of-pataudi-boys-navy-blue-printed-pure-cotton-kurta/16279730/buy
A271: Leather Structured Shoulder Bag with Quilted | B271: Da Milano | C271: 0 | D271: 0 | E271: 12999 | F271: 12999 | G271: Onesize | H271: handbags/da-milano/da-milano-black-textured-leather-structured-shoulder-bag-with-quilted/18003228/buy
A272: Men Kurta | B272: CAVALLO by Linen Club | C272: 0 | D272: 0 | E272: 1899 | F272: 1329 | G272: S,M,L,XL | H272: kurtas/cavallo-by-linen-club/cavallo-by-linen-club-men-blue-thread-work-kurta/18306840/buy
...

Sheet clean data 
A1: product_name | B1: brand_name | C1: rating | D1: rating_count | E1: marked_price | F1: discounted_price | G1: sizes | H1: product_category | I1: brand_symbol | J1: product_id | K1: revenue | L1: discount
A2: Pure Georgette Bandhani Saree | B2: Mitera | C2: 3.6 | D2: 5 | E2: 6727 | F2: 1681 | G2: Onesize | H2: sarees | I2: mitera | J2: 17141476 | K2: =D2*F2 -> 8405 | L2: =((E2-F2)/E2)*100 -> 75.011149
A3: Men Accessory Gift Set | B3: WildHorn | C3: 4.5 | D3: 80 | E3: 2999 | F3: 1049 | G3: Onesize | H3: accessory-gift-set | I3: wildhorn | J3: 1410357 | K3: =D3*F3 -> 83920 | L3: =((E3-F3)/E3)*100 -> 65.021674
A4: Self-Design Thermal Set | B4: Kanvin | C4: 4.6 | D4: 42 | E4: 1598 | F4: 1278 | G4: S,M,L,XL,XXL | H4: thermal-set | I4: kanvin | J4: 2223155 | K4: =D4*F4 -> 53676 | L4: =((E4-F4)/E4)*100 -> 20.025031 | O4: THIS CLEAN DATA CONTAINS ALL ROWS EXCEPT THOSE WHO HAVE 0 RATING.
A5: Men Slim Fit T-shirt | B5: Jack & Jones | C5: 3.7 | D5: 7 | E5: 1299 | F5: 649 | G5: S,M,L,XL,XXL | H5: tshirts | I5: jack--jones | J5: 15430520 | K5: =D5*F5 -> 4543 | L5: =((E5-F5)/E5)*100 -> 50.038491
A6: Outdoor Rapid-Dry Jacket | B6: HRX by Hrithik Roshan | C6: 4.4 | D6: 186 | E6: 2799 | F6: 1679 | G6: XS,S,M,L,XL | H6: jackets | I6: hrx-by-hrithik-roshan | J6: 11953112 | K6: =D6*F6 -> 312294 | L6: =((E6-F6)/E6)*100 -> 40.014291
A7: Floral Maxi Dress | B7: Nayo | C7: 4 | D7: 7 | E7: 1999 | F7: 799 | G7: S,M,L,XL,XXL | H7: dresses | I7: nayo | J7: 17634118 | K7: =D7*F7 -> 5593 | L7: =((E7-F7)/E7)*100 -> 60.030015
A8: Women Ribbed Fitted Top | B8: DressBerry | C8: 4.2 | D8: 252 | E8: 999 | F8: 399 | G8: XS,S,M,L,XL | H8: tops | I8: dressberry | J8: 11003624 | K8: =D8*F8 -> 100548 | L8: =((E8-F8)/E8)*100 -> 60.06006
A9: Men Gold-Toned Brooch | B9: Alvaro Castagnino | C9: 4.9 | D9: 10 | E9: 999 | F9: 399 | G9: Onesize | H9: brooch | I9: alvaro-castagnino | J9: 17426638 | K9: =D9*F9 -> 3990 | L9: =((E9-F9)/E9)*100 -> 60.06006
A10: Printed Lounge T-shirt | B10: ETC | C10: 4.3 | D10: 52 | E10: 499 | F10: 324 | G10: S,M,L,XL | H10: lounge-tshirts | I10: etc | J10: 12442110 | K10: =D10*F10 -> 16848 | L10: =((E10-F10)/E10)*100 -> 35.07014
A11: Men Solid Sliders | B11: Power | C11: 3.9 | D11: 34 | E11: 746 | F11: 671 | G11: UK6,UK7,UK8,UK9,UK10,UK11 | H11: flip-flops | I11: power | J11: 12453854 | K11: =D11*F11 -> 22814 | L11: =((E11-F11)/E11)*100 -> 10.053619
A12: Women Skinny Fit Jeans | B12: Mast & Harbour | C12: 4 | D12: 105 | E12: 1799 | F12: 809 | G12: 26,28,30,32,34,36 | H12: jeans | I12: mast--harbour | J12: 12310178 | K12: =D12*F12 -> 84945 | L12: =((E12-F12)/E12)*100 -> 55.030573
A13: Unisex Round Sunglasses | B13: WROGN | C13: 4.1 | D13: 338 | E13: 2899 | F13: 1884 | G13: M | H13: sunglasses | I13: wrogn | J13: 2385219 | K13: =D13*F13 -> 636792 | L13: =((E13-F13)/E13)*100 -> 35.012073
A14: Women Tummy & Thigh Shapewear | B14: Dermawear | C14: 2 | D14: 5 | E14: 1349 | F14: 1349 | G14: S,M,L,XL,XXL,3XL | H14: shapewear | I14: dermawear | J14: 17667772 | K14: =D14*F14 -> 6745 | L14: =((E14-F14)/E14)*100 -> 0
A15: Women Cotton Printed Tracksuit | B15: Duke | C15: 4.4 | D15: 14 | E15: 2995 | F15: 1797 | G15: S,M,L,XL,XXL | H15: tracksuits | I15: duke | J15: 15152634 | K15: =D15*F15 -> 25158 | L15: =((E15-F15)/E15)*100 -> 40
A16: Pack of 2 Minimizer Bras | B16: Floret | C16: 4.3 | D16: 239 | E16: 898 | F16: 853 | G16: 30C,32C,34C,36C,38C,40C | H16: bra | I16: floret | J16: 11169978 | K16: =D16*F16 -> 203867 | L16: =((E16-F16)/E16)*100 -> 5.0111359
... A369: Men Analogue Watch | B369: TIMESMITH | C369: 3.9 | D369: 7 | E369: 2499 | F369: 399 | G369: Onesize | H369: watches | I369: timesmith | J369: 11135920 | K369: =D369*F369 -> 2793 | L369: =((E369-F369)/E369)*100 -> 84.033613
A370: Men Leather Formal Belt | B370: United Colors of Benetton | C370: 3.4 | D370: 7 | E370: 2999 | F370: 899 | G370: 34 | H370: belts | I370: united-colors-of-benetton | J370: 8488829 | K370: =D370*F370 -> 6293 | L370: =((E370-F370)/E370)*100 -> 70.023341
A371: Cone Shade Armed Sconces | B371: Homesake | C371: 4.3 | D371: 21 | E371: 3300 | F371: 1199 | G371: Onesize | H371: wall-lamps | I371: homesake | J371: 9246303 | K371: =D371*F371 -> 25179 | L371: =((E371-F371)/E371)*100 -> 63.666667
A372: Women Slim Fit Regular Trousers | B372: FORCLAZ By Decathlon | C372: 5 | D372: 6 | E372: 2999 | F372: 2579 | G372: 26,28,30,32,34,36 | H372: trousers | I372: forclaz-by-decathlon | J372: 13168086 | K372: =D372*F372 -> 15474 | L372: =((E372-F372)/E372)*100 -> 14.004668
A373: Embroidered High-Low Top | B373: Mayra | C373: 3.1 | D373: 36 | E373: 1095 | F373: 459 | G373: S,M,L,XL | H373: tops | I373: mayra | J373: 11091590 | K373: =D373*F373 -> 16524 | L373: =((E373-F373)/E373)*100 -> 58.082192
A374: Printed Kurta with Palazzos | B374: FABRIC FITOOR | C374: 4.5 | D374: 15 | E374: 4599 | F374: 1057 | G374: S,M,L,XL,XXL,3XL | H374: kurta-sets | I374: fabric-fitoor | J374: 12103850 | K374: =D374*F374 -> 15855 | L374: =((E374-F374)/E374)*100 -> 77.016743
A375: Women Yoke Design Kurta with Trousers With Dupatta | B375: Varanga | C375: 1 | D375: 2 | E375: 4999 | F375: 1699 | G375: S,M,L,XL,XXL | H375: kurta-sets | I375: varanga | J375: 13983922 | K375: =D375*F375 -> 3398 | L375: =((E375-F375)/E375)*100 -> 66.013203
A376: Men Typography Printed T-shirt | B376: HERE&NOW | C376: 3.8 | D376: 5 | E376: 949 | F376: 284 | G376: S,M,L,XL | H376: tshirts | I376: herenow | J376: 16260732 | K376: =D376*F376 -> 1420 | L376: =((E376-F376)/E376)*100 -> 70.073762
A377: Unisex Anti Theft Backpack | B377: F Gear | C377: 4.5 | D377: 191 | E377: 4995 | F377: 1898 | G377: Onesize | H377: backpacks | I377: f-gear | J377: 4385679 | K377: =D377*F377 -> 362518 | L377: =((E377-F377)/E377)*100 -> 62.002002
A378: Men Solid Kurta with Pyjamas | B378: VASTRAMAY | C378: 4.4 | D378: 43 | E378: 4499 | F378: 2249 | G378: S,M,L,XL,XXL,3XL | H378: kurta-sets | I378: vastramay | J378: 4369942 | K378: =D378*F378 -> 96707 | L378: =((E378-F378)/E378)*100 -> 50.011114
A379: Girls Embroidered Kurta with Palazzos With Dupatta | B379: Biba | C379: 4.1 | D379: 7 | E379: 3299 | F379: 1649 | G379: 9Y,11Y,13Y,15Y | H379: kurta-sets | I379: biba | J379: 14847260 | K379: =D379*F379 -> 11543 | L379: =((E379-F379)/E379)*100 -> 50.015156
A380: PU Structured Sling Bag | B380: Exotic | C380: 4.7 | D380: 9 | E380: 2599 | F380: 1074 | G380: S | H380: handbags | I380: exotic | J380: 17394202 | K380: =D380*F380 -> 9666 | L380: =((E380-F380)/E380)*100 -> 58.676414
A381: AD-Studded Mangalsutra Set | B381: Brandsoon | C381: 5 | D381: 2 | E381: 2528 | F381: 353 | G381: Onesize | H381: mangalsutra | I381: brandsoon | J381: 17403044 | K381: =D381*F381 -> 706 | L381: =((E381-F381)/E381)*100 -> 86.036392
A382: Women Embroidered Rozana Kurta | B382: House of Pataudi | C382: 4.2 | D382: 5 | E382: 3199 | F382: 1919 | G382: XS,S,M,L,XL,XXL | H382: kurtas | I382: house-of-pataudi | J382: 13721048 | K382: =D382*F382 -> 9595 | L382: =((E382-F382)/E382)*100 -> 40.012504
... A717: Scoop Neck Fitted Top | B717: Miaz Lifestyle | C717: 3.5 | D717: 88 | E717: 999 | F717: 589 | G717: XS,S,M,L,XL,XXL | H717: tops | I717: miaz-lifestyle | J717: 15112544 | K717: =D717*F717 -> 51832 | L717: =((E717-F717)/E717)*100 -> 41.041041
A718: Slim Fit Casual Shirt | B718: Louis Philippe Jeans | C718: 3.3 | D718: 3 | E718: 2049 | F718: 1229 | G718: 44 | H718: shirts | I718: louis-philippe-jeans | J718: 14225978 | K718: =D718*F718 -> 3687 | L718: =((E718-F718)/E718)*100 -> 40.019522
A719: Girls Layered A-Line Dress | B719: pspeaches | C719: 4.4 | D719: 54 | E719: 1499 | F719: 524 | G719: 2-3Y,3-4Y,4-5Y,5-6Y,6-7Y,7-8Y,8-9Y,9-10Y,10-11Y,11-12Y | H719: dresses | I719: pspeaches | J719: 13882872 | K719: =D719*F719 -> 28296 | L719: =((E719-F719)/E719)*100 -> 65.043362
A720: Women Printed Kurta with Palazzos | B720: Moda Rapido | C720: 3.9 | D720: 8 | E720: 4399 | F720: 1099 | G720: XS,S,M,L,XL,XXL | H720: kurta-sets | I720: moda-rapido | J720: 14430866 | K720: =D720*F720 -> 8792 | L720: =((E720-F720)/E720)*100 -> 75.017049
A721: Suede Block Mules with Buckles | B721: VALIOSAA | C721: 3.5 | D721: 6 | E721: 2499 | F721: 1474 | G721: EURO35,EURO36,EURO37,EURO38,EURO39,EURO40 | H721: heels | I721: valiosaa | J721: 15777288 | K721: =D721*F721 -> 8844 | L721: =((E721-F721)/E721)*100 -> 41.016407
A722: Women Floral Embroidered Kurta | B722: KALINI | C722: 2.8 | D722: 5 | E722: 1249 | F722: 399 | G722: M,L,XL,XXL,3XL | H722: kurtas | I722: kalini | J722: 17227692 | K722: =D722*F722 -> 1995 | L722: =((E722-F722)/E722)*100 -> 68.054444
A723: Women Solid Block Heels | B723: Padvesh | C723: 3.4 | D723: 5 | E723: 1299 | F723: 649 | G723: EURO38,EURO39,EURO40,EURO41,EURO42 | H723: heels | I723: padvesh | J723: 12826644 | K723: =D723*F723 -> 3245 | L723: =((E723-F723)/E723)*100 -> 50.038491
A724: Women Cotton Solid Pullover | B724: MANGO | C724: 4.2 | D724: 9 | E724: 2990 | F724: 1794 | G724: XS,S,M,L | H724: sweaters | I724: mango | J724: 15721508 | K724: =D724*F724 -> 16146 | L724: =((E724-F724)/E724)*100 -> 40
A725: Women High Waist Tummy & Thigh Control Seamless Shapewear | B725: SECRETS BY ZEROKAATA | C725: 3.8 | D725: 138 | E725: 1000 | F725: 820 | G725: M,L,XL | H725: shapewear | I725: secrets-by-zerokaata | J725: 13549778 | K725: =D725*F725 -> 113160 | L725: =((E725-F725)/E725)*100 -> 18
A726: Geometric Regular Top | B726: Trend Arrest | C726: 4.2 | D726: 9 | E726: 1299 | F726: 480 | G726: XS,S,M,L,XL | H726: tops | I726: trend-arrest | J726: 16247900 | K726: =D726*F726 -> 4320 | L726: =((E726-F726)/E726)*100 -> 63.048499
...

Sheet analysis
C2: UNCLEAN DATA | G2: CLEAN DATA
C3: Total Number of Products | D3: =COUNTA(#REF!) -> 1 | G3: Total Number of Products | H3: =COUNTA(#REF!) -> 1
C4: Number of Unique Brands | D4: =COUNTA(_xlfn.UNIQUE(#REF!)) -> 1 | G4: Number of Unique Brands | H4: 2139
C5: Average Rating | D5: =AVERAGE(Sheet1!C2:C24325) -> 2.1832264 | G5: Average Rating | H5: =AVERAGE('clean data '!C2:C11439) -> 4.1597744
C6: Most Expensive Product (MP) | D6: =MAX(Sheet1!E1:E24325) -> 44950 | G6: Most Expensive Product (MP) | H6: =MAX('clean data '!E2:E11439) -> 33900
C7: Least Expensive Product (MP) | D7: =MIN(Sheet1!E2:E24325) -> 55 | G7: Least Expensive Product (MP) | H7: =MIN('clean data '!E2:E11439) -> 55
C8: Most Expensive Product (DP) | D8: =MAX(Sheet1!F2:F24325) -> 40900 | G8: Most Expensive Product (DP) | H8: =MAX('clean data '!F2:F11439) -> 33900
C9: Least Expensive Product (DP) | D9: =MIN(Sheet1!F2:F24325) -> 49 | G9: Least Expensive Product (DP) | H9: =MIN('clean data '!F2:F11439) -> 49
C10: Total Traffic on Platform | D10: =SUM(Sheet1!D2:D24325) -> 1558289 | G10: Total Traffic on Platform | H10: =SUM('clean data '!D2:D11439) -> 1404665

Sheet pivot concept
A3: brand_name | B3: Average of rating | E3: brand_name | F3: Sum of rating_count
A4: Bitterlime | B4: 4.1083333 | E4: Bitterlime | F4: 1163
A5: Blush 9 Maternity | B5: 4.45 | E5: Blush 9 Maternity | F5: 204
A6: Bodycare Kids | B6: 4.5857143 | E6: Bodycare Kids | F6: 386
A7: Dollar Bigboss | B7: 4.0333333 | E7: Dollar Bigboss | F7: 306
A8: DOT & KEY | B8: 4.6 | E8: DOT & KEY | F8: 40
A9: Grand Total | B9: 4.28 | E9: Grand Total | F9: 2099

Sheet brand_pivot
E1: BRAND PIVOT
A3: brand_name | B3: Average of marked_price | C3: Average of discounted_price | E3: brand_name | F3: Average of rating | H3: brand_name | I3: Sum of rating_count | K3: brand_name | L3: Sum of revenue | N3: brand_name | O3: Count of product_category
A4: Jockey | B4: 547.23077 | C4: 547.23077 | E4: Jockey | F4: 4.4358974 | H4: Jockey | I4: 7629 | K4: Jockey | L4: 3783102 | N4: Jockey | O4: 78
A5: Louis Philippe | B5: 3531.3729 | C5: 2568.3898 | E5: Louis Philippe | F5: 4.2 | H5: Louis Philippe | I5: 3210 | K5: Louis Philippe | L5: 5693266 | N5: Louis Philippe | O5: 59
A6: Mast & Harbour | B6: 1860.5385 | C6: 826.76154 | E6: Mast & Harbour | F6: 4.0996154 | H6: Mast & Harbour | I6: 21292 | K6: Mast & Harbour | L6: 16617334 | N6: Mast & Harbour | O6: 260
A7: Nike | B7: 2895 | C7: 2796.2308 | E7: Nike | F7: 4.4307692 | H7: Nike | I7: 306 | K7: Nike | L7: 766322 | N7: Nike | O7: 13
A8: Wildcraft | B8: 3123.037 | C8: 2954 | E8: Wildcraft | F8: 4.3407407 | H8: Wildcraft | I8: 1298 | K8: Wildcraft | L8: 3237483 | N8: Wildcraft | O8: 27
A9: Grand Total | B9: 1960.4851 | C9: 1202.0275 | E9: Grand Total | F9: 4.1979405 | H9: Grand Total | I9: 33735 | K9: Grand Total | L9: 30097507 | N9: Grand Total | O9: 437

Sheet brand_dashboard
H2: BRAND DASHBOARD

Sheet product_pivot
H2: PRODUCT PIVOT
B5: product_category | C5: Average of marked_price | D5: Average of discounted_price | F5: product_category | G5: Sum of rating_count | I5: product_category | J5: Count of brand_name
B6: jeans | C6: 2328.7133 | D6: 1275.763 | F6: jeans | G6: 34767 | I6: jeans | J6: 422
B7: shirts | C7: 1947.2538 | D7: 1066.9015 | F7: shirts | G7: 48765 | I7: shirts | J7: 650
B8: shorts | C8: 1401.4837 | D8: 851.89302 | F8: shorts | G8: 11559 | I8: shorts | J8: 215
B9: speakers | C9: 3197.2 | D9: 1619 | F9: speakers | G9: 471 | I9: speakers | J9: 5
B10: tshirts | C10: 1207.0473 | D10: 677.15254 | F10: tshirts | G10: 94149 | I10: tshirts | J10: 1121
B11: Grand Total | C11: 1624.0518 | D11: 904.3506 | F11: Grand Total | G11: 189711 | I11: Grand Total | J11: 2413

Sheet product_dashboard
J1: PRODUCT DASHBOARD
